//
//  FutureTests.swift
//  DelorianTests
//
//  Created by George Webster on 10/15/19.
//  Copyright Â© 2019 George Webster. All rights reserved.
//

import XCTest
@testable import Delorian

class FutureTests: XCTestCase {
    let backgroundQueue = DispatchQueue.global(qos: .userInitiated)
}

extension FutureTests {

    func testAsync() {

        let exp = expectation(description: "async")

        let sut = Future<Int>(on: DispatchQueue.main) { callback in
            self.backgroundQueue.asyncAfter(deadline: .now() + 2) {
                callback(Result<Int, Error>.success(23))
            }
        }
        sut.onResult { (result) in
            XCTAssertNotNil(result.value)
            XCTAssert(result.value == 23)
            exp.fulfill()
        }

        wait(for: [exp], timeout: 10)
    }

    func testAsync_multipleCallbacks() {

        let sut = Future<Int>(on: DispatchQueue.main) { callback in
            self.backgroundQueue.asyncAfter(deadline: .now() + 2) {
                callback(Result<Int, Error>.success(42))
            }
        }
        let exps = [expectation(description: "1st async"), expectation(description: "2nd async"), expectation(description: "3rd async")]
        exps.forEach { exp in
            sut.onResult { (result) in
                XCTAssertNotNil(result.value)
                XCTAssert(result.value == 42)
                exp.fulfill()
            }
        }
        wait(for: exps, timeout: 10)
    }


    func testAsync_failure() {

        let exp = expectation(description: "async")

        let sut = Future<String>(on: DispatchQueue.main) { callback in
            self.backgroundQueue.asyncAfter(deadline: .now() + 2) {
                callback(Result<String, Error>.failure(NSError(domain: "", code: 23, userInfo: nil)))
            }
        }
        sut.onResult { (result) in
            _ = result.map { _ in
                XCTFail("should have no value to map over")
            }
            _ = result.mapError { (error) -> Error in
                let nsError = error as NSError
                XCTAssert(nsError.code == 23)
                return error
            }
            exp.fulfill()
        }

        wait(for: [exp], timeout: 10)
    }


    func testFlatMap() {

        let exp = expectation(description: "async")

        _ = Future<String>(on: DispatchQueue.main) { completion in
            self.backgroundQueue.asyncAfter(deadline: .now() + 2) {
                completion(Result<String, Error>.success("back to the future!"))
            }
        }.flatMap { value in
            return Future<String>(on: DispatchQueue.main) { completion in
                completion(Result<String, Error>.success(value.uppercased()))
            }
        }.onResult { (result) in
            XCTAssertNotNil(result.value)
            XCTAssert(result.value == "BACK TO THE FUTURE!")
            exp.fulfill()
        }

        wait(for: [exp], timeout: 10)

    }
}
